Workbook

Sheet 2025
A1: id | B1: empresa_tic | C1: ano_tri | D1: data_ini | E1: data_fim | F1: conta | G1: descricao | H1: valor | I1: tipo_balanco
A2: 6558577 | B2: VIVA | C2: 20254T | D2: 46022 | E2: 46022 | F2: 1 | G2: Ativo Total | H2: 4722693388 | I2: DFs Consolidadas
A3: 6558578 | B3: VIVA | C3: 20254T | D3: 46022 | E3: 46022 | F3: 1.01 | G3: Ativo Circulante | H3: 3064599866 | I3: DFs Consolidadas
A4: 6558579 | B4: VIVA | C4: 20254T | D4: 46022 | E4: 46022 | F4: 1.01.01 | G4: Caixa e Equivalentes de Caixa | H4: 365433346 | I4: DFs Consolidadas
A5: 6558580 | B5: VIVA | C5: 20254T | D5: 46022 | E5: 46022 | F5: 1.01.01.01 | G5: Caixas e equivalentes de caixa | H5: 365433346 | I5: DFs Consolidadas
A6: 6558581 | B6: VIVA | C6: 20254T | D6: 46022 | E6: 46022 | F6: 1.01.02 | G6: Aplicações Financeiras | H6: 33210886 | I6: DFs Consolidadas
A7: 6558582 | B7: VIVA | C7: 20254T | D7: 46022 | E7: 46022 | F7: 1.01.02.01 | G7: Aplicações Financeiras Avaliadas a Valor Justo através do Resultado | H7: 0 | I7: DFs Consolidadas
A8: 6558583 | B8: VIVA | C8: 20254T | D8: 46022 | E8: 46022 | F8: 1.01.02.01.01 | G8: Títulos para Negociação | H8: 0 | I8: DFs Consolidadas
A9: 6558584 | B9: VIVA | C9: 20254T | D9: 46022 | E9: 46022 | F9: 1.01.02.01.02 | G9: Títulos Designados a Valor Justo | H9: 0 | I9: DFs Consolidadas
A10: 6558585 | B10: VIVA | C10: 20254T | D10: 46022 | E10: 46022 | F10: 1.01.02.01.03 | G10: Títulos e valores mobiliários | H10: 0 | I10: DFs Consolidadas
A11: 6558586 | B11: VIVA | C11: 20254T | D11: 46022 | E11: 46022 | F11: 1.01.02.02 | G11: Aplicações Financeiras Avaliadas a Valor Justo através de Outros Resultados Abrangentes | H11: 0 | I11: DFs Consolidadas
A12: 6558587 | B12: VIVA | C12: 20254T | D12: 46022 | E12: 46022 | F12: 1.01.02.03 | G12: Aplicações Financeiras Avaliadas ao Custo Amortizado | H12: 33210886 | I12: DFs Consolidadas
A13: 6558588 | B13: VIVA | C13: 20254T | D13: 46022 | E13: 46022 | F13: 1.01.03 | G13: Contas a Receber | H13: 989601403 | I13: DFs Consolidadas
... A362: 6558937 | B362: VIVA | C362: 20254T | D362: 45658 | E362: 46022 | F362: 7.08.05 | G362: Outros | H362: 0 | I362: DFs Consolidadas

Sheet 2024
A1: id | B1: empresa_tic | C1: ano_tri | D1: data_ini | E1: data_fim | F1: conta | G1: descricao | H1: valor | I1: tipo_balanco
A2: 6164772 | B2: VIVA | C2: 20244T | D2: 45657 | E2: 45657 | F2: 1 | G2: Ativo Total | H2: 4273730310 | I2: DFs Consolidadas
A3: 6164773 | B3: VIVA | C3: 20244T | D3: 45657 | E3: 45657 | F3: 1.01 | G3: Ativo Circulante | H3: 2781887721 | I3: DFs Consolidadas
A4: 6164774 | B4: VIVA | C4: 20244T | D4: 45657 | E4: 45657 | F4: 1.01.01 | G4: Caixa e Equivalentes de Caixa | H4: 278153431 | I4: DFs Consolidadas
A5: 6164775 | B5: VIVA | C5: 20244T | D5: 45657 | E5: 45657 | F5: 1.01.01.01 | G5: Caixas e equivalentes de caixa | H5: 278153431 | I5: DFs Consolidadas
A6: 6164776 | B6: VIVA | C6: 20244T | D6: 45657 | E6: 45657 | F6: 1.01.02 | G6: Aplicações Financeiras | H6: 4529633 | I6: DFs Consolidadas
A7: 6164777 | B7: VIVA | C7: 20244T | D7: 45657 | E7: 45657 | F7: 1.01.02.01 | G7: Aplicações Financeiras Avaliadas a Valor Justo através do Resultado | H7: 0 | I7: DFs Consolidadas
A8: 6164778 | B8: VIVA | C8: 20244T | D8: 45657 | E8: 45657 | F8: 1.01.02.01.01 | G8: Títulos para Negociação | H8: 0 | I8: DFs Consolidadas
A9: 6164779 | B9: VIVA | C9: 20244T | D9: 45657 | E9: 45657 | F9: 1.01.02.01.02 | G9: Títulos Designados a Valor Justo | H9: 0 | I9: DFs Consolidadas
A10: 6164780 | B10: VIVA | C10: 20244T | D10: 45657 | E10: 45657 | F10: 1.01.02.01.03 | G10: Títulos e valores mobiliários | H10: 0 | I10: DFs Consolidadas
A11: 6164781 | B11: VIVA | C11: 20244T | D11: 45657 | E11: 45657 | F11: 1.01.02.02 | G11: Aplicações Financeiras Avaliadas a Valor Justo através de Outros Resultados Abrangentes | H11: 0 | I11: DFs Consolidadas
A12: 6164782 | B12: VIVA | C12: 20244T | D12: 45657 | E12: 45657 | F12: 1.01.02.03 | G12: Aplicações Financeiras Avaliadas ao Custo Amortizado | H12: 4529633 | I12: DFs Consolidadas
A13: 6164783 | B13: VIVA | C13: 20244T | D13: 45657 | E13: 45657 | F13: 1.01.03 | G13: Contas a Receber | H13: 955208115 | I13: DFs Consolidadas
... A358: 6165128 | B358: VIVA | C358: 20244T | D358: 45292 | E358: 45657 | F358: 7.08.05 | G358: Outros | H358: 0 | I358: DFs Consolidadas

Sheet 2023
A1: id | B1: empresa_tic | C1: ano_tri | D1: data_ini | E1: data_fim | F1: conta | G1: descricao | H1: valor | I1: tipo_balanco
A2: 5666405 | B2: VIVA | C2: 20234T | D2: 45291 | E2: 45291 | F2: 1 | G2: Ativo Total | H2: 3241590055 | I2: DFs Consolidadas
A3: 5666406 | B3: VIVA | C3: 20234T | D3: 45291 | E3: 45291 | F3: 1.01 | G3: Ativo Circulante | H3: 2056580123 | I3: DFs Consolidadas
A4: 5666407 | B4: VIVA | C4: 20234T | D4: 45291 | E4: 45291 | F4: 1.01.01 | G4: Caixa e Equivalentes de Caixa | H4: 221495208 | I4: DFs Consolidadas
A5: 5666408 | B5: VIVA | C5: 20234T | D5: 45291 | E5: 45291 | F5: 1.01.01.01 | G5: Caixas e equivalentes de caixa | H5: 221495208 | I5: DFs Consolidadas
A6: 5666409 | B6: VIVA | C6: 20234T | D6: 45291 | E6: 45291 | F6: 1.01.02 | G6: Aplicações Financeiras | H6: 82994526 | I6: DFs Consolidadas
A7: 5666410 | B7: VIVA | C7: 20234T | D7: 45291 | E7: 45291 | F7: 1.01.02.01 | G7: Aplicações Financeiras Avaliadas a Valor Justo através do Resultado | H7: 0 | I7: DFs Consolidadas
A8: 5666411 | B8: VIVA | C8: 20234T | D8: 45291 | E8: 45291 | F8: 1.01.02.01.01 | G8: Títulos para Negociação | H8: 0 | I8: DFs Consolidadas
A9: 5666412 | B9: VIVA | C9: 20234T | D9: 45291 | E9: 45291 | F9: 1.01.02.01.02 | G9: Títulos Designados a Valor Justo | H9: 0 | I9: DFs Consolidadas
A10: 5666413 | B10: VIVA | C10: 20234T | D10: 45291 | E10: 45291 | F10: 1.01.02.01.03 | G10: Títulos e valores mobiliários | H10: 0 | I10: DFs Consolidadas
A11: 5666414 | B11: VIVA | C11: 20234T | D11: 45291 | E11: 45291 | F11: 1.01.02.02 | G11: Aplicações Financeiras Avaliadas a Valor Justo através de Outros Resultados Abrangentes | H11: 0 | I11: DFs Consolidadas
A12: 5666415 | B12: VIVA | C12: 20234T | D12: 45291 | E12: 45291 | F12: 1.01.02.03 | G12: Aplicações Financeiras Avaliadas ao Custo Amortizado | H12: 82994526 | I12: DFs Consolidadas
A13: 5666416 | B13: VIVA | C13: 20234T | D13: 45291 | E13: 45291 | F13: 1.01.03 | G13: Contas a Receber | H13: 830832349 | I13: DFs Consolidadas
... A353: 5666756 | B353: VIVA | C353: 20234T | D353: 44927 | E353: 45291 | F353: 7.08.05 | G353: Outros | H353: 0 | I353: DFs Consolidadas

Sheet Indicadores
B2: Indicadores de Liquidez | C2: Sigla | D2: Fórmulas | F2: 2025 | H2: 2024
B3: Capital Circulante Líquido | C3: CCL | D3: AC - PC | F3: ='Rascunho Inicial'!D4 -> 2220651547 | H3: ='Rascunho Inicial'!E4 -> 1786201847
B4: Índice de Liquides Corrente | C4: LC | D4: AC/PC | F4: ='Rascunho Inicial'!D5 -> 3.6312648 | H4: ='Rascunho Inicial'!E5 -> 2.7939411
B5: Índice de Liquides Seca | C5: LS | D5: (AC - EST - DA) /PC | F5: ='Rascunho Inicial'!D6 -> 1.8788751 | H5: ='Rascunho Inicial'!E6 -> 1.4555896
B6: Índice de Liquides Absoluta | C6: LA | D6: DISPONIVEL /PC | F6: ='Rascunho Inicial'!D7 -> 0.43300441 | H6: ='Rascunho Inicial'!E7 -> 0.27935862
B7: Índice de Liquides Geral | C7: LG | D7: AC + ARLP / PC +PNC | F7: ='Rascunho Inicial'!D8 -> 2.0908875 | H7: ='Rascunho Inicial'!E8 -> 1.8872448
B9: Indicadores de Atividade | C9: Sigla | D9: Fórmulas | F9: 2025 | H9: 2024
B10: Prazo Médio de Estocagem | C10: PME | D10: (ESTOQUE MÉDIO/CMV)*360 | F10: ='Rascunho Inicial'!D9 -> 549.19789 | H10: ='Rascunho Inicial'!E9 -> 496.35948
B11: Giro do Estoque | C11: GE | D11: 360/PME | F11: ='Rascunho Inicial'!D10 -> 0.65550142 | H11: ='Rascunho Inicial'!E10 -> 0.7252808
B12: Prazo Médio de Recebimento de Vendas | C12: PMRV | D12: (CLIENTES MÉDIO /RECEITA)*360 | F12: ='Rascunho Inicial'!D11 -> 124.74705 | H12: ='Rascunho Inicial'!E11 -> 115.66373
B13: Prazo Médio de Pagamento de Fornecedores | C13: PMPF | D13: (FORNECEDORES MÉDIO/COMPRAS)*360 | F13: ='Rascunho Inicial'!D13 -> 77.490215 | H13: ='Rascunho Inicial'!E13 -> 80.241412
B14: Ciclo Operacional | C14: CO | D14: PME+PMRV | F14: ='Rascunho Inicial'!D14 -> 673.94494 | H14: ='Rascunho Inicial'!E14 -> 612.02321
B15: Ciclo Financeiro | C15: CF | D15: CO-PMPF | F15: ='Rascunho Inicial'!D15 -> 596.45472 | H15: ='Rascunho Inicial'!E15 -> 531.7818
B16: Ciclo Econômico | C16: CE | D16: PME | F16: ='Rascunho Inicial'!D16 -> 549.19789 | H16: ='Rascunho Inicial'!E16 -> 496.35948
B18: Indicadores de Capital de Giro | C18: Sigla | D18: Fórmulas | F18: 2025 | H18: 2024
B19: Capital de Giro Líquido | C19: CDG | D19: CDG = AC - PC | F19: ='Rascunho Inicial'!D25 -> 2220651547 | H19: ='Rascunho Inicial'!E25 -> 1786201847
B20: Saldo em Tesouraria | C20: ST | D20: ST = ACF - PCF | F20: ='Rascunho Inicial'!D23 -> 45258425 | H20: ='Rascunho Inicial'!E23 -> -88876930
B21: Necessidade de Capital de Giro | C21: NCG | D21: NCG = ACO - PCO | F21: ='Rascunho Inicial'!D24 -> 2175393122 | H21: ='Rascunho Inicial'!E24 -> 1875078777
B23: Indicadores de Estrutura de Capital | C23: Sigla | D23: Fórmulas | F23: 2025 | H23: 2024
B24: Relação de Capital Próprio e de Terceiros | C24: RCPT | D24: PASSIVO/PL | F24: ='Rascunho Inicial'!D26 -> 1.6011481 | H24: ='Rascunho Inicial'!E26 -> 1.7115851
B25: Endividamento Geral | C25: EG | D25: PASSIVO/PASSIVO+PL | F25: ='Rascunho Inicial'!D27 -> 0.61555438 | H25: ='Rascunho Inicial'!E27 -> 0.63121201
B26: Solvência Geral | C26: SG | D26: ATIVO TOTAL/PASSIVO | F26: ='Rascunho Inicial'!D28 -> 1 | H26: ='Rascunho Inicial'!E28 -> 1
B27: Composição do Endividamento | C27: CE | D27: PC/PASSIVO | F27: ='Rascunho Inicial'!D29 -> 0.17870064 | H27: ='Rascunho Inicial'!E29 -> 0.23297817
B28: Imobilização do Patrimônio Líquido | C28: IPL | D28: ATIVOS FIXOS(3is)/PL | F28: ='Rascunho Inicial'!D30 -> 0.32389411 | H28: ='Rascunho Inicial'!E30 -> 0.34168644
B29: Passivo Oneroso | C29: PO | D29: PASSIVOS QUE GERAM DESPESAS FINANCEIRAS | F29: ='2025'!H142+'2025'!H105 -> 531275707 | G29: ='2025'!I105+'2025'!I142 -> #VALUE! | H29: ='2024'!H142+'2024'!H105 -> 398560704 | I29: ='2025'!K105+'2025'!K142 -> 0
B30: Dívida Líquida | C30: DL | D30: PO - (DISPONÍVEL + AP. FINANCEIRA) | F30: =F29-('2025'!H4+'2025'!H6) -> 132631475 | H30: =H29-('2024'!H4+'2024'!H6) -> 115877640
B31: Investimento | C31: INV | D31: PO + PL | F31: =F29+'2025'!H181 -> 3480842548 | H31: =H29+'2024'!H181 -> 2895503691
B32: Capital Oneroso | C32: CO | D32: DÍVIDA LÍQUIDA + PL | F32: =F30+'2025'!H181 -> 3082198316 | H32: =H30+'2024'!H181 -> 2612820627
B33: Relação dívida Líquida - PL | C33: na | D33: DL/PL | F33: =F30/'2025'!H181 -> 0.044966425 | H33: =H30/'2024'!H181 -> 0.046407804
B34: Relação divida líquida e CO | C34: na | D34: DÍVIDA LÍQUIDA /dívida líquida + PL | F34: =F30/(F30+'2025'!H181) -> 0.043031454 | H34: =H30/(H30+'2024'!H181) -> 0.044349635
B36: Indicadores de Custo do Capital | C36: Sigla | D36: Fórmulas | F36: 2025 | H36: 2024
B37: Percentual da Dívida no Investimento | C37: Wi | D37: PO/Investimento | F37: =F29/F31 -> 0.15262848 | H37: =H29/H31 -> 0.13764814
B38: Percentual da Equity no Investimento | C38: We | D38: PL/Investimento | F38: ='2025'!H181/Indicadores!F31 -> 0.84737152 | H38: ='2024'!H181/Indicadores!H31 -> 0.86235186
B39: Despesa Financeira Líquida | C39: DFL | D39: DF - BENEFÍCIO TRIBUTÁRIO | F39: =ABS('2025'!H232)-Indicadores!F40 -> 1.7013025e+08 | G39: =ABS('2025'!I232)-Indicadores!G40 -> #VALUE! | H39: =ABS('2024'!H232)-Indicadores!H40 -> 94545840
B40: Benefício Tributário da Dívida | C40: BT | D40: DESPESA FINANCEIRA X ALÍQUOTA IR/CSLL | F40: =('2025'!H232*Indicadores!F41)*(-1) -> 38129649 | H40: =('2024'!H232*Indicadores!H41)*(-1) -> 19736309
B41: Aliquota Efetiva IR/CSLL | C41: % IR | D41: PROVISÃO IR/CSLL / LAIR | F41: =('2025'!H236/'2025'!H234)*(-1) -> 0.18308685 | H41: =('2024'!H236/'2024'!H234)*(-1) -> 0.17269809
B42: Custo da Dívida | C42: Ki | D42: Despesa financeira / PO | F42: =170130251/531275707 -> 0.32022968 | H42: =('2024'!H232/Indicadores!H29)*(-1) -> 0.28673712
B43: Custo Médio Ponderado de Capital | C43: CMPC | D43: Wi x Ki + We x Ke | F43: =F37*F42+F38*0.16 -> 0.18445561 | H43: =H37*H42+H38*0.16 -> 0.17744513
B45: Indicadores de Lucratividade e Rentabilidade | C45: Sigla | D45: Fórmulas | F45: 2025 | H45: 2024
B46: Margem Bruta | C46: MB | D46: LUCRO BRUTO/RECEITA LÍQUIDA | F46: ='2025'!H215/'2025'!H211 -> 0.69554018 | H46: ='2024'!H215/'2024'!H211 -> 0.70234624
...

Sheet Rascunho Inicial
C3: Indicadores | D3: 2025 | E3: 2024 | G3: DRE Gerencial | J3: 2025 | L3: 2024
C4: Capital Circulante Líquido (AC-PC) | D4: ='2025'!H3-'2025'!H77 -> 2220651547 | E4: ='2024'!H3-'2024'!H77 -> 1786201847 | G4: Receita Líquida | J4: ='2025'!H211 -> 3026581564 | L4: ='2024'!H211 -> 2577113417
C5: Liquidez Corrente (AC/PC) | D5: ='2025'!H3/'2025'!H77 -> 3.6312648 | E5: ='2024'!H3/'2024'!H77 -> 2.7939411 | G5: Lucro Bruto | J5: ='2025'!H215 -> 2105109081 | L5: ='2024'!H215 -> 1810025931
C6: Liquidez Seca ((AC-Est-DA)/PC | D6: =('2025'!H3-'2025'!H19)/'2025'!H77 -> 1.8788751 | E6: =('2024'!H3-'2024'!H19)/'2024'!H77 -> 1.4555896 | G6: EBITDA | J6: ='2025'!H228+'2025'!H253 -> 889179247 | L6: ='2024'!H228+'2024'!H253 -> 838115320
C7: Liquidez Absoluta (Caixa e Equiv/PC) | D7: ='2025'!H5/'2025'!H77 -> 0.43300441 | E7: ='2024'!H5/'2024'!H77 -> 0.27935862 | G7: EBIT | J7: ='2025'!H228 -> 726321236 | L7: ='2024'!H228 -> 683585305
C8: Liquidez Geral ((AC + ARLP)/(PC + PNC)) | D8: =('2025'!H3+'2025'!H34)/('2025'!H77+'2025'!H141) -> 2.0908875 | E8: =('2024'!H3+'2024'!H34)/('2024'!H77+'2024'!H141) -> 1.8872448 | G8: NOPAT | J8: =J7-'2025'!H234 -> 138522723 | L8: =L7-'2024'!H234 -> 57347164
C9: PME (((EstInic + EstFin)/2)/CMV)x360 | D9: =ABS((('2024'!H19+'2025'!H19)/2)/'2025'!H213)*360 -> 549.19789 | E9: =ABS((('2023'!H19+'2024'!H19)/2)/'2024'!H213)*360 -> 496.35948
C10: Giro de Estoque (360/PME) | D10: =360/D9 -> 0.65550142 | E10: =360/E9 -> 0.7252808
C11: PMRV (((ClientesInic + ClientesFin)/2)/Receita)x360 | D11: =((('2023'!H14+'2024'!H14)/2)/'2024'!H211)*360 -> 124.74705 | E11: =((('2024'!H14+'2025'!H14)/2)/'2025'!H211)*360 -> 115.66373 | G11: N° de ações da empresa | J11: 236197769 | L11: Unidade
B12: - | C12: Compras ((CMV) + Estinoc - Estfin) | D12: =ABS(('2024'!H213)+'2023'!H19- '2024'!H19) -> 1316958801 | E12: =ABS(('2025'!H213)+'2024'!H19- '2025'!H19) -> 1067821159 | G12: VPA (PL/N° de ações da empresa) | J12: ='2025'!H181/'Rascunho Inicial'!J11 -> 12.4877 | L12: Valor Monetário
C13: PMPF (((FornecedorInic + FornecedorFin)/2)/Compras)x360 | D13: =((('2024'!H84+'2025'!H84)/2)/D12)*360 -> 77.490215 | E13: =((('2023'!H82+'2024'!H84)/2)/E12)*360 -> 80.241412 | G13: P/VP (Preço da Ação/VPA) | L13: Valor Monetário
C14: Ciclo Operacional (PME + PMRV) | D14: =D9+D11 -> 673.94494 | E14: =E9+E11 -> 612.02321 | G14: LPA (Lucro líquido/N° de ações) | J14: ='2025'!H242/'Rascunho Inicial'!J11 -> 2.6228118 | L14: Valor Monetário
C15: Ciclo Financeiro (CO - PMPF) | D15: =D14-D13 -> 596.45472 | E15: =E14-E13 -> 531.7818 | G15: P/L (Preço da Ação/LPA) | L15: Vezes
C16: Ciclo Econômico (PME) | D16: =D9 -> 549.19789 | E16: =E9 -> 496.35948
C17: Ativo Circulante Financeiro - ACF | D17: ='2025'!H5+'2025'!H6 -> 398644232 | E17: ='2024'!H5+'2024'!H6 -> 282683064
C18: Ativo Circulante Operacional - ACO | D18: ='2025'!H13+'2025'!H19+'2025'!H22+'2025'!H26 -> 2665955634 | E18: ='2024'!H13+'2024'!H19+'2024'!H22+'2024'!H26 -> 2499204657
C19: Ativo Circulante | D19: =D17+D18 -> 3064599866 | E19: =E17+E18 -> 2781887721
C20: Passivo Circulante Financeiro - PCF | D20: ='2025'!H105+'2025'!H120+'2025'!H121+'2025'!H122+'2025'!H117 -> 353385807 | E20: ='2024'!H105+'2024'!H120+'2024'!H121+'2024'!H122+'2024'!H117 -> 371559994
C21: Passivo Circulante Operacional - PCO | D21: ='2025'!H78+'2025'!H84+'2025'!H91+'2025'!H126+'2025'!H127+'2025'!H124 -> 490562512 | E21: ='2024'!H78+'2024'!H84+'2024'!H91+'2024'!H126+'2024'!H127+'2024'!H124 -> 624125880
C22: Passivo Circulante | D22: =D20+D21 -> 843948319 | E22: =E20+E21 -> 995685874
C23: Saldo em Tesouraria - ST (ACF-PCF) | D23: =D17-D20 -> 45258425 | E23: =E17-E20 -> -88876930
C24: Necessidade de Capital de Giro - NCG (ACO-PCO) | D24: =D18-D21 -> 2175393122 | E24: =E18-E21 -> 1875078777
C25: Capital de Giro Líquido - CGL (AC-PC) | D25: =D19-D22 -> 2220651547 | E25: =E19-E22 -> 1786201847
C26: Relação de Capitais (Passivo/PL) | D26: ='2025'!H76/'2025'!H181 -> 1.6011481 | E26: ='2024'!H76/'2024'!H181 -> 1.7115851
C27: Endividamento Geral (Passivo/(Passivo + PL)) | D27: ='2025'!H76/('2025'!H76+'2025'!H181) -> 0.61555438 | E27: ='2024'!H76/('2024'!H76+'2024'!H181) -> 0.63121201
C28: Solvência Geral (Ativo/Passivo) | D28: ='2025'!H2/'2025'!H76 -> 1 | E28: ='2024'!H2/'2024'!H76 -> 1
C29: Composição do Endividamento (PC/Passivo) | D29: ='2025'!H77/'2025'!H76 -> 0.17870064 | E29: ='2024'!H77/'2024'!H76 -> 0.23297817
C30: Imobilização do PL (Ativos Fixos/PL) | D30: ='2025'!H66/'2025'!H181 -> 0.32389411 | E30: ='2024'!H66/'2024'!H181 -> 0.34168644
