Workbook

Sheet 2023 4
A1: id | B1: empresa_tic | C1: ano_tri | D1: data_ini | E1: data_fim | F1: conta | G1: descricao | H1: valor | I1: tipo_balanco
A2: 5646687 | B2: NATU | C2: 20234T | D2: 45291 | E2: 45291 | F2: 1 | G2: Ativo Total | H2: 42747015 | I2: DFs Consolidadas
A3: 5646688 | B3: NATU | C3: 20234T | D3: 45291 | E3: 45291 | F3: 1.01 | G3: Ativo Circulante | H3: 15987222 | I3: DFs Consolidadas
A4: 5646689 | B4: NATU | C4: 20234T | D4: 45291 | E4: 45291 | F4: 1.01.01 | G4: Caixa e Equivalentes de Caixa | H4: 3750944 | I4: DFs Consolidadas
A5: 5646690 | B5: NATU | C5: 20234T | D5: 45291 | E5: 45291 | F5: 1.01.02 | G5: Aplicações Financeiras | H5: 4024056 | I5: DFs Consolidadas
A6: 5646691 | B6: NATU | C6: 20234T | D6: 45291 | E6: 45291 | F6: 1.01.02.01 | G6: Aplicações Financeiras Avaliadas a Valor Justo através do Resultado | H6: 0 | I6: DFs Consolidadas
A7: 5646692 | B7: NATU | C7: 20234T | D7: 45291 | E7: 45291 | F7: 1.01.02.01.01 | G7: Títulos para Negociação | H7: 0 | I7: DFs Consolidadas
A8: 5646693 | B8: NATU | C8: 20234T | D8: 45291 | E8: 45291 | F8: 1.01.02.01.02 | G8: Títulos Designados a Valor Justo | H8: 0 | I8: DFs Consolidadas
A9: 5646694 | B9: NATU | C9: 20234T | D9: 45291 | E9: 45291 | F9: 1.01.02.02 | G9: Aplicações Financeiras Avaliadas a Valor Justo através de Outros Resultados Abrangentes | H9: 0 | I9: DFs Consolidadas
A10: 5646695 | B10: NATU | C10: 20234T | D10: 45291 | E10: 45291 | F10: 1.01.02.03 | G10: Aplicações Financeiras Avaliadas ao Custo Amortizado | H10: 0 | I10: DFs Consolidadas
A11: 5646696 | B11: NATU | C11: 20234T | D11: 45291 | E11: 45291 | F11: 1.01.03 | G11: Contas a Receber | H11: 3547310 | I11: DFs Consolidadas
A12: 5646697 | B12: NATU | C12: 20234T | D12: 45291 | E12: 45291 | F12: 1.01.03.01 | G12: Clientes | H12: 3547310 | I12: DFs Consolidadas
A13: 5646698 | B13: NATU | C13: 20234T | D13: 45291 | E13: 45291 | F13: 1.01.03.01.01 | G13: Contas a receber - Alienação de controladas | H13: 22915 | I13: DFs Consolidadas
... A326: 5647011 | B326: NATU | C326: 20234T | D326: 44927 | E326: 45291 | F326: 7.08.05.01 | G326: Operações Descontinuadas | H326: 0 | I326: DFs Consolidadas

Sheet 2024 4
A1: id | B1: empresa_tic | C1: ano_tri | D1: data_ini | E1: data_fim | F1: conta | G1: descricao | H1: valor | I1: tipo_balanco | J1: Coluna1
A2: 6139171 | B2: NATU | C2: 20244T | D2: 45657 | E2: 45657 | F2: 1 | G2: Ativo Total | H2: 37133423 | I2: DFs Consolidadas
A3: 6139172 | B3: NATU | C3: 20244T | D3: 45657 | E3: 45657 | F3: 1.01 | G3: Ativo Circulante | H3: 15139547 | I3: DFs Consolidadas
A4: 6139173 | B4: NATU | C4: 20244T | D4: 45657 | E4: 45657 | F4: 1.01.01 | G4: Caixa e Equivalentes de Caixa | H4: 2641683 | I4: DFs Consolidadas
A5: 6139174 | B5: NATU | C5: 20244T | D5: 45657 | E5: 45657 | F5: 1.01.02 | G5: Aplicações Financeiras | H5: 1816443 | I5: DFs Consolidadas
A6: 6139175 | B6: NATU | C6: 20244T | D6: 45657 | E6: 45657 | F6: 1.01.02.01 | G6: Aplicações Financeiras Avaliadas a Valor Justo através do Resultado | H6: 0 | I6: DFs Consolidadas
A7: 6139176 | B7: NATU | C7: 20244T | D7: 45657 | E7: 45657 | F7: 1.01.02.01.01 | G7: Títulos para Negociação | H7: 0 | I7: DFs Consolidadas
A8: 6139177 | B8: NATU | C8: 20244T | D8: 45657 | E8: 45657 | F8: 1.01.02.01.02 | G8: Títulos Designados a Valor Justo | H8: 0 | I8: DFs Consolidadas
A9: 6139178 | B9: NATU | C9: 20244T | D9: 45657 | E9: 45657 | F9: 1.01.02.02 | G9: Aplicações Financeiras Avaliadas a Valor Justo através de Outros Resultados Abrangentes | H9: 0 | I9: DFs Consolidadas
A10: 6139179 | B10: NATU | C10: 20244T | D10: 45657 | E10: 45657 | F10: 1.01.02.03 | G10: Aplicações Financeiras Avaliadas ao Custo Amortizado | H10: 0 | I10: DFs Consolidadas
A11: 6139180 | B11: NATU | C11: 20244T | D11: 45657 | E11: 45657 | F11: 1.01.03 | G11: Contas a Receber | H11: 5280765 | I11: DFs Consolidadas
A12: 6139181 | B12: NATU | C12: 20244T | D12: 45657 | E12: 45657 | F12: 1.01.03.01 | G12: Clientes | H12: 5280765 | I12: DFs Consolidadas
A13: 6139182 | B13: NATU | C13: 20244T | D13: 45657 | E13: 45657 | F13: 1.01.03.01.01 | G13: Contas a receber - Alienação de controladas | H13: 0 | I13: DFs Consolidadas
... A186: 6139355 | B186: NATU | C186: 20244T | D186: 45657 | E186: 45657 | F186: 2.03.08 | G186: Outros Resultados Abrangentes | H186: 0 | I186: DFs Consolidadas
A187: 6139356 | B187: NATU | C187: 20244T | D187: 45657 | E187: 45657 | F187: 2.03.09 | G187: Participação dos Acionistas Não Controladores | H187: 179 | I187: DFs Consolidadas | J187: DRE GERENCIAL 2024
A188: 6139357 | B188: NATU | C188: 20244T | D188: 45292 | E188: 45657 | F188: 3.01 | G188: Receita de Venda de Bens e/ou Serviços | H188: 24089804 | I188: DFs Consolidadas
A189: 6139358 | B189: NATU | C189: 20244T | D189: 45292 | E189: 45657 | F189: 3.02 | G189: Custo dos Bens e/ou Serviços Vendidos | H189: -8372597 | I189: DFs Consolidadas | J189: Receita Líquida: 24089804
A190: 6139359 | B190: NATU | C190: 20244T | D190: 45292 | E190: 45657 | F190: 3.03 | G190: Resultado Bruto | H190: 15717207 | I190: DFs Consolidadas
A191: 6139360 | B191: NATU | C191: 20244T | D191: 45292 | E191: 45657 | F191: 3.04 | G191: Despesas/Receitas Operacionais | H191: -14809136 | I191: DFs Consolidadas
A192: 6139361 | B192: NATU | C192: 20244T | D192: 45292 | E192: 45657 | F192: 3.04.01 | G192: Despesas com Vendas | H192: -9968893 | I192: DFs Consolidadas | J192: Lucro Bruto: 15717207
A193: 6139362 | B193: NATU | C193: 20244T | D193: 45292 | E193: 45657 | F193: 3.04.02 | G193: Despesas Gerais e Administrativas | H193: -3358347 | I193: DFs Consolidadas
A194: 6139363 | B194: NATU | C194: 20244T | D194: 45292 | E194: 45657 | F194: 3.04.03 | G194: Perdas pela Não Recuperabilidade de Ativos | H194: -480182 | I194: DFs Consolidadas
A195: 6139364 | B195: NATU | C195: 20244T | D195: 45292 | E195: 45657 | F195: 3.04.04 | G195: Outras Receitas Operacionais | H195: -1001714 | I195: DFs Consolidadas | J195: EBIT:
A196: 6139365 | B196: NATU | C196: 20244T | D196: 45292 | E196: 45657 | F196: 3.04.05 | G196: Outras Despesas Operacionais | H196: 0 | I196: DFs Consolidadas | J196: =H190-(-H191) -> 908071
A197: 6139366 | B197: NATU | C197: 20244T | D197: 45292 | E197: 45657 | F197: 3.04.06 | G197: Resultado de Equivalência Patrimonial | H197: 0 | I197: DFs Consolidadas
A198: 6139367 | B198: NATU | C198: 20244T | D198: 45292 | E198: 45657 | F198: 3.05 | G198: Resultado Antes do Resultado Financeiro e dos Tributos | H198: 908071 | I198: DFs Consolidadas
A199: 6139368 | B199: NATU | C199: 20244T | D199: 45292 | E199: 45657 | F199: 3.06 | G199: Resultado Financeiro | H199: -692809 | I199: DFs Consolidadas | J199: EBITDA = EBIT + Dep/Amort:
A200: 6139369 | B200: NATU | C200: 20244T | D200: 45292 | E200: 45657 | F200: 3.06.01 | G200: Receitas Financeiras | H200: 0 | I200: DFs Consolidadas | J200: =J196+H222 -> 1876881
A201: 6139370 | B201: NATU | C201: 20244T | D201: 45292 | E201: 45657 | F201: 3.06.01.01 | G201: Resultado Financeiro Líquido | H201: 0 | I201: DFs Consolidadas
A202: 6139371 | B202: NATU | C202: 20244T | D202: 45292 | E202: 45657 | F202: 3.06.02 | G202: Despesas Financeiras | H202: -692809 | I202: DFs Consolidadas
A203: 6139372 | B203: NATU | C203: 20244T | D203: 45292 | E203: 45657 | F203: 3.06.02.01 | G203: Resultado financeiro liquido | H203: -692809 | I203: DFs Consolidadas | J203: NOPAT = EBIT - IR/CSLL corrente:
A204: 6139373 | B204: NATU | C204: 20244T | D204: 45292 | E204: 45657 | F204: 3.07 | G204: Resultado Antes dos Tributos sobre o Lucro | H204: 215262 | I204: DFs Consolidadas | J204: =J196-H206 -> 908071
A205: 6139374 | B205: NATU | C205: 20244T | D205: 45292 | E205: 45657 | F205: 3.08 | G205: Imposto de Renda e Contribuição Social sobre o Lucro | H205: ='2025 4'!J197-'2025 4'!H206 -> 1415968 | I205: DFs Consolidadas
A206: 6139375 | B206: NATU | C206: 20244T | D206: 45292 | E206: 45657 | F206: 3.08.01 | G206: Corrente | H206: 0 | I206: DFs Consolidadas
A207: 6139376 | B207: NATU | C207: 20244T | D207: 45292 | E207: 45657 | F207: 3.08.02 | G207: Diferido | H207: 0 | I207: DFs Consolidadas
A208: 6139377 | B208: NATU | C208: 20244T | D208: 45292 | E208: 45657 | F208: 3.09 | G208: Resultado Líquido das Operações Continuadas | H208: -742108 | I208: DFs Consolidadas
A209: 6139378 | B209: NATU | C209: 20244T | D209: 45292 | E209: 45657 | F209: 3.10 | G209: Resultado Líquido de Operações Descontinuadas | H209: -8187572 | I209: DFs Consolidadas
A210: 6139379 | B210: NATU | C210: 20244T | D210: 45292 | E210: 45657 | F210: 3.10.01 | G210: Lucro/Prejuízo Líquido das Operações Descontinuadas | H210: -8187572 | I210: DFs Consolidadas
A211: 6139380 | B211: NATU | C211: 20244T | D211: 45292 | E211: 45657 | F211: 3.10.02 | G211: Ganhos/Perdas Líquidas sobre Ativos de Operações Descontinuadas | H211: 0 | I211: DFs Consolidadas
A212: 6139381 | B212: NATU | C212: 20244T | D212: 45292 | E212: 45657 | F212: 3.11 | G212: Lucro/Prejuízo Consolidado do Período | H212: -8929680 | I212: DFs Consolidadas
...

Sheet 2025 4
A1: id | B1: empresa_tic | C1: ano_tri | D1: data_ini | E1: data_fim | F1: conta | G1: descricao | H1: valor | I1: tipo_balanco | J1: Coluna1
A2: 6574908 | B2: NATU | C2: 20254T | D2: 46022 | E2: 46022 | F2: 1 | G2: Ativo Total | H2: 28971321 | I2: DFs Consolidadas
A3: 6574909 | B3: NATU | C3: 20254T | D3: 46022 | E3: 46022 | F3: 1.01 | G3: Ativo Circulante | H3: 12214304 | I3: DFs Consolidadas
A4: 6574910 | B4: NATU | C4: 20254T | D4: 46022 | E4: 46022 | F4: 1.01.01 | G4: Caixa e Equivalentes de Caixa | H4: 1490706 | I4: DFs Consolidadas
A5: 6574911 | B5: NATU | C5: 20254T | D5: 46022 | E5: 46022 | F5: 1.01.02 | G5: Aplicações Financeiras | H5: 1180547 | I5: DFs Consolidadas
A6: 6574912 | B6: NATU | C6: 20254T | D6: 46022 | E6: 46022 | F6: 1.01.02.01 | G6: Aplicações Financeiras Avaliadas a Valor Justo através do Resultado | H6: 0 | I6: DFs Consolidadas
A7: 6574913 | B7: NATU | C7: 20254T | D7: 46022 | E7: 46022 | F7: 1.01.02.01.01 | G7: Títulos para Negociação | H7: 0 | I7: DFs Consolidadas
A8: 6574914 | B8: NATU | C8: 20254T | D8: 46022 | E8: 46022 | F8: 1.01.02.01.02 | G8: Títulos Designados a Valor Justo | H8: 0 | I8: DFs Consolidadas
A9: 6574915 | B9: NATU | C9: 20254T | D9: 46022 | E9: 46022 | F9: 1.01.02.02 | G9: Aplicações Financeiras Avaliadas a Valor Justo através de Outros Resultados Abrangentes | H9: 0 | I9: DFs Consolidadas
A10: 6574916 | B10: NATU | C10: 20254T | D10: 46022 | E10: 46022 | F10: 1.01.02.03 | G10: Aplicações Financeiras Avaliadas ao Custo Amortizado | H10: 0 | I10: DFs Consolidadas
A11: 6574917 | B11: NATU | C11: 20254T | D11: 46022 | E11: 46022 | F11: 1.01.03 | G11: Contas a Receber | H11: 4849142 | I11: DFs Consolidadas
A12: 6574918 | B12: NATU | C12: 20254T | D12: 46022 | E12: 46022 | F12: 1.01.03.01 | G12: Clientes | H12: 4680026 | I12: DFs Consolidadas
A13: 6574919 | B13: NATU | C13: 20254T | D13: 46022 | E13: 46022 | F13: 1.01.03.02 | G13: Outras Contas a Receber | H13: 169116 | I13: DFs Consolidadas
... A187: 6575093 | B187: NATU | C187: 20254T | D187: 46022 | E187: 46022 | F187: 2.03.08 | G187: Outros Resultados Abrangentes | H187: 0 | I187: DFs Consolidadas
A188: 6575094 | B188: NATU | C188: 20254T | D188: 46022 | E188: 46022 | F188: 2.03.09 | G188: Participação dos Acionistas Não Controladores | H188: 0 | I188: DFs Consolidadas | J188: DRE GERENCIAL
A189: 6575095 | B189: NATU | C189: 20254T | D189: 45658 | E189: 46022 | F189: 3.01 | G189: Receita de Venda de Bens e/ou Serviços | H189: 21823488 | I189: DFs Consolidadas
A190: 6575096 | B190: NATU | C190: 20254T | D190: 45658 | E190: 46022 | F190: 3.02 | G190: Custo dos Bens e/ou Serviços Vendidos | H190: -7287168 | I190: DFs Consolidadas | J190: Receita Líquida: 21823488
A191: 6575097 | B191: NATU | C191: 20254T | D191: 45658 | E191: 46022 | F191: 3.03 | G191: Resultado Bruto | H191: 14536320 | I191: DFs Consolidadas
A192: 6575098 | B192: NATU | C192: 20254T | D192: 45658 | E192: 46022 | F192: 3.04 | G192: Despesas/Receitas Operacionais | H192: -13120352 | I192: DFs Consolidadas
A193: 6575099 | B193: NATU | C193: 20254T | D193: 45658 | E193: 46022 | F193: 3.04.01 | G193: Despesas com Vendas | H193: -8612735 | I193: DFs Consolidadas | J193: Lucro Bruto: 14536320
A194: 6575100 | B194: NATU | C194: 20254T | D194: 45658 | E194: 46022 | F194: 3.04.02 | G194: Despesas Gerais e Administrativas | H194: -3096489 | I194: DFs Consolidadas
A195: 6575101 | B195: NATU | C195: 20254T | D195: 45658 | E195: 46022 | F195: 3.04.03 | G195: Perdas pela Não Recuperabilidade de Ativos | H195: -544698 | I195: DFs Consolidadas
A196: 6575102 | B196: NATU | C196: 20254T | D196: 45658 | E196: 46022 | F196: 3.04.04 | G196: Outras Receitas Operacionais | H196: 0 | I196: DFs Consolidadas | J196: EBIT:
A197: 6575103 | B197: NATU | C197: 20254T | D197: 45658 | E197: 46022 | F197: 3.04.05 | G197: Outras Despesas Operacionais | H197: -866430 | I197: DFs Consolidadas | J197: =H191-(-H192) -> 1415968
A198: 6575104 | B198: NATU | C198: 20254T | D198: 45658 | E198: 46022 | F198: 3.04.06 | G198: Resultado de Equivalência Patrimonial | H198: 0 | I198: DFs Consolidadas
A199: 6575105 | B199: NATU | C199: 20254T | D199: 45658 | E199: 46022 | F199: 3.05 | G199: Resultado Antes do Resultado Financeiro e dos Tributos | H199: 1415968 | I199: DFs Consolidadas
A200: 6575106 | B200: NATU | C200: 20254T | D200: 45658 | E200: 46022 | F200: 3.06 | G200: Resultado Financeiro | H200: -866918 | I200: DFs Consolidadas | J200: EBITDA = EBIT + Dep/Amort:
A201: 6575107 | B201: NATU | C201: 20254T | D201: 45658 | E201: 46022 | F201: 3.06.01 | G201: Receitas Financeiras | H201: 0 | I201: DFs Consolidadas | J201: =J197+H223 -> 2229900
A202: 6575108 | B202: NATU | C202: 20254T | D202: 45658 | E202: 46022 | F202: 3.06.02 | G202: Despesas Financeiras | H202: -866918 | I202: DFs Consolidadas
A203: 6575109 | B203: NATU | C203: 20254T | D203: 45658 | E203: 46022 | F203: 3.06.02.01 | G203: Resultado financeiro liquido | H203: -866918 | I203: DFs Consolidadas
A204: 6575110 | B204: NATU | C204: 20254T | D204: 45658 | E204: 46022 | F204: 3.07 | G204: Resultado Antes dos Tributos sobre o Lucro | H204: 549050 | I204: DFs Consolidadas | J204: NOPAT = EBIT - IR/CSLL corrente:
A205: 6575111 | B205: NATU | C205: 20254T | D205: 45658 | E205: 46022 | F205: 3.08 | G205: Imposto de Renda e Contribuição Social sobre o Lucro | H205: -20070 | I205: DFs Consolidadas | J205: =J197-H206 -> 1415968
A206: 6575112 | B206: NATU | C206: 20254T | D206: 45658 | E206: 46022 | F206: 3.08.01 | G206: Corrente | H206: 0 | I206: DFs Consolidadas
A207: 6575113 | B207: NATU | C207: 20254T | D207: 45658 | E207: 46022 | F207: 3.08.02 | G207: Diferido | H207: 0 | I207: DFs Consolidadas
A208: 6575114 | B208: NATU | C208: 20254T | D208: 45658 | E208: 46022 | F208: 3.09 | G208: Resultado Líquido das Operações Continuadas | H208: 528980 | I208: DFs Consolidadas
A209: 6575115 | B209: NATU | C209: 20254T | D209: 45658 | E209: 46022 | F209: 3.10 | G209: Resultado Líquido de Operações Descontinuadas | H209: -2314218 | I209: DFs Consolidadas
A210: 6575116 | B210: NATU | C210: 20254T | D210: 45658 | E210: 46022 | F210: 3.10.01 | G210: Lucro/Prejuízo Líquido das Operações Descontinuadas | H210: -2314218 | I210: DFs Consolidadas
A211: 6575117 | B211: NATU | C211: 20254T | D211: 45658 | E211: 46022 | F211: 3.10.02 | G211: Ganhos/Perdas Líquidas sobre Ativos de Operações Descontinuadas | H211: 0 | I211: DFs Consolidadas
A212: 6575118 | B212: NATU | C212: 20254T | D212: 45658 | E212: 46022 | F212: 3.11 | G212: Lucro/Prejuízo Consolidado do Período | H212: -1785238 | I212: DFs Consolidadas
A213: 6575119 | B213: NATU | C213: 20254T | D213: 45658 | E213: 46022 | F213: 3.11.01 | G213: Atribuído a Sócios da Empresa Controladora | H213: -1785238 | I213: DFs Consolidadas
...

Sheet Indicadores
A1: Indicadores | B1: 2025 | C1: 2024 | I1: Sigla | J1: Significado | K1: Onde aparece
A2: Capital Circulante Líquido (AC-PC) | B2: ='2025 4'!H3-'2025 4'!H73 -> 4830465 | C2: ='2024 4'!H3-'2024 4'!H73 -> 5532058 | I2: AC | J2: Ativo Circulante | K2: Balanço Patrimonial
A3: Liquidez Corrente (AC/PC) | B3: =Tabela3[[#This Row],[valor]]/'2025 4'!H73 -> 1.6541942 | C3: =Tabela2[[#This Row],[valor]]/'2024 4'!H73 -> 1.5758069 | I3: PC | J3: Passivo Circulante | K3: Balanço Patrimonial
A4: Liquidez Seca ((AC-Est-DA)/PC) | B4: =('2025 4'!H3-'2025 4'!H16-'2025 4'!H44)/'2025 4'!H73 -> 1.2525594 | C4: =('2024 4'!H3-'2024 4'!H16-'2024 4'!H44)/'2024 4'!H73 -> 1.2241903 | I4: PL | J4: Patrimônio Líquido | K4: Balanço Patrimonial
A5: Liquidez Absoluta (Caixa e Equiv/PC) | B5: =('2025 4'!H4/'2025 4'!H73) -> 0.20188766 | C5: ='2024 4'!H4/'2024 4'!H73 -> 0.27496081 | I5: PNC | J5: Passivo Não Circulante | K5: Balanço Patrimonial
A6: Liquidez Geral ((AC + ARLP)/(PC + PNC)) | B6: =(('2025 4'!H3+'2025 4'!H31)/('2025 4'!H73+'2025 4'!H120)) -> 0.96562267 | C6: =(('2024 4'!H3+'2024 4'!H31)/('2024 4'!H73+'2024 4'!H118)) -> 0.93736174 | I6: ARLP | J6: Ativo Realizável a Longo Prazo | K6: Balanço Patrimonial
A7: PME (((EstInic + EstFin)/2)/CMV)x360 | B7: =ABS((('2025 4'!H16+'2024 4'!H16)/2)/'2025 4'!H190)*360 -> 156.6969 | C7: =ABS((('2024 4'!H16+'2023 4'!H16)/2)/'2024 4'!H189)*360 -> 139.00089 | I7: Est | J7: Estoque | K7: Balanço Patrimonial
A8: Giro de Estoque (360/PME) | B8: =(360/B7) -> 2.297429 | C8: =(360/C7) -> 2.5899114 | I8: EstInic | J8: Estoque Inicial | K8: Balanço Patrimonial
A9: PMRV (((ClientesInic + ClientesFin)/2)/Receita)x360 | B9: =((('2025 4'!H12+'2024 4'!H12)/2)/'2025 4'!H189)*360 -> 82.156545 | C9: =((('2024 4'!H12+'2023 4'!H12)/2)/'2024 4'!H188)*360 -> 65.963737 | I9: EstFin | J9: Estoque Final | K9: Balanço Patrimonial
A10: Compras ((CMV) + EstInic - EstFin) | B10: =ABS('2025 4'!H190)+'2025 4'!H16-'2024 4'!H16 -> 6874623 | C10: =ABS('2024 4'!H189)+'2024 4'!H16-'2023 4'!H16 -> 8663354 | I10: DA | J10: Despesas Antecipadas | K10: Balanço Patrimonial
A11: PMPF (((FornecedorInic + FornecedorFin)/2)/Compras)x360 | B11: =((('2025 4'!H77+'2024 4'!H77)/2)/Indicadores!B10)*360 -> 294.4663 | C11: =((('2024 4'!H77+'2023 4'!H77)/2)/Indicadores!C10)*360 -> 241.93482 | I11: CMV | J11: Custo das Mercadorias Vendidas | K11: DRE
A12: Ciclo Operacional (PME + PMRV) | B12: =(B7+B9) -> 238.85344 | C12: =(C7+C9) -> 204.96463 | I12: ClientesInic | J12: Saldo de Clientes no início do período | K12: Balanço Patrimonial
A13: Ciclo Financeiro (CO - PMPF) | B13: =(B12-B11) -> -55.612857 | C13: =(C12-C11) -> -36.970189 | I13: ClientesFin | J13: Saldo de Clientes no fim do período | K13: Balanço Patrimonial
A14: Ciclo Econômico (PME) | B14: =B7 -> 156.6969 | C14: =C7 -> 139.00089 | I14: FornecedorInic | J14: Saldo de Fornecedores no início do período | K14: Balanço Patrimonial
A15: Ativo Circulante Financeiro (CEC + AF) | B15: ='2025 4'!H4+'2025 4'!H5 -> 2671253 | C15: ='2024 4'!H4+'2024 4'!H5 -> 4458126 | I15: FornecedorFin | J15: Saldo de Fornecedores no fim do período | K15: Balanço Patrimonial
A16: Ativo Circulante Operacional (AC - ACF) | B16: =('2025 4'!H3-Indicadores!B15) -> 9543051 | C16: =('2024 4'!H3-Indicadores!C15) -> 10681421 | I16: Receita | J16: Receita Líquida de Vendas | K16: DRE
A17: Ativo Circulante | B17: ='2025 4'!H3 -> 12214304 | C17: ='2024 4'!H3 -> 15139547 | I17: Compras | J17: Total de Compras do período | K17: DRE / Apuração de estoque
A18: Passivo Circulante Financeiro (EF + DE) | B18: =('2025 4'!H89+'2025 4'!H92) -> 100502 | C18: =('2024 4'!H87+'2024 4'!H91) -> 55890 | I18: Caixa e Equiv | J18: Caixa e Equivalentes de Caixa | K18: Balanço Patrimonial
A19: Passivo Circulante Operacional (PC - PCF) | B19: =('2025 4'!H73-Indicadores!B18) -> 7283337 | C19: =('2024 4'!H73-Indicadores!C18) -> 9551599 | I19: Ativos Fixos | J19: Ativo Imobilizado | K19: Balanço Patrimonial
A20: Passivo Circulante | B20: ='2025 4'!H73 -> 7383839 | C20: ='2024 4'!H73 -> 9607489 | I20: Passivo | J20: Passivo Total (PC + PNC) | K20: Balanço Patrimonial
A21: Saldo em Tesouraria - ST (ACF-PCF) | B21: =B15-B18 -> 2570751 | C21: =C15-C18 -> 4402236 | I21: PME | J21: Prazo Médio de Estocagem | K21: Indicador calculado
A22: Necessidade de Capital de Giro - NCG (ACO-PCO) | B22: =B16-B19 -> 2259714 | C22: =C16-C19 -> 1129822 | I22: PMRV | J22: Prazo Médio de Recebimento de Vendas | K22: Indicador calculado
A23: Capital de Giro Líquido - CGL (AC-PC) | B23: =B17-B20 -> 4830465 | C23: =C17-C20 -> 5532058 | I23: PMPF | J23: Prazo Médio de Pagamento a Fornecedores | K23: Indicador calculado
A24: Relação de Capitais (Passivo/PL) | B24: ='2025 4'!H72/'2025 4'!H161 -> 2.2325629 | C24: ='2024 4'!H72/'2024 4'!H159 -> 2.3694743 | I24: CO | J24: Ciclo Operacional | K24: Indicador calculado
A25: Endividamento Geral (Passivo/(Passivo + PL)) | B25: =('2025 4'!H72/('2025 4'!H72+'2025 4'!H161)) -> 0.69064794 | C25: =('2024 4'!H72/('2024 4'!H72+'2024 4'!H159)) -> 0.7032178 | I25: ACF | J25: Ativo Circulante Financeiro | K25: Modelo Fleuriet
A26: Solvência Geral (Ativo/Passivo) | B26: ='2025 4'!H2/'2025 4'!H72 -> 1 | C26: ='2024 4'!H2/'2024 4'!H72 -> 1 | I26: ACO | J26: Ativo Circulante Operacional | K26: Modelo Fleuriet
A27: Composição do Endividamento (PC/Passivo) | B27: ='2025 4'!H73/'2025 4'!H72 -> 0.25486718 | C27: ='2024 4'!H73/'2024 4'!H72 -> 0.25872888 | I27: PCF | J27: Passivo Circulante Financeiro | K27: Modelo Fleuriet | M27: \
A28: Imobilização do PL (Ativos Fixos/PL) | B28: ='2025 4'!H64/'2025 4'!H161 -> 0.24165332 | C28: ='2024 4'!H64/'2024 4'!H159 -> 0.2894994 | I28: PCO | J28: Passivo Circulante Operacional | K28: Modelo Fleuriet
I29: ST | J29: Saldo em Tesouraria | K29: Modelo Fleuriet
I30: NCG | J30: Necessidade de Capital de Giro | K30: Modelo Fleuriet
I31: CGL | J31: Capital de Giro Líquido | K31: Modelo Fleuriet
I32: CCL | J32: Capital Circulante Liquido
