Workbook

Sheet 2023
A1: id | B1: empresa_tic | C1: ano_tri | D1: data_ini | E1: data_fim | F1: conta | G1: descricao | H1: valor | I1: tipo_balanco
A2: 5654830 | B2: LREN | C2: 20234T | D2: 45291 | E2: 45291 | F2: 1 | G2: Ativo Total | H2: 20490638 | I2: DFs Consolidadas
A3: 5654831 | B3: LREN | C3: 20234T | D3: 45291 | E3: 45291 | F3: 1.01 | G3: Ativo Circulante | H3: 12191644 | I3: DFs Consolidadas
A4: 5654832 | B4: LREN | C4: 20234T | D4: 45291 | E4: 45291 | F4: 1.01.01 | G4: Caixa e Equivalentes de Caixa | H4: 2532187 | I4: DFs Consolidadas
A5: 5654833 | B5: LREN | C5: 20234T | D5: 45291 | E5: 45291 | F5: 1.01.02 | G5: Aplicações Financeiras | H5: 571655 | I5: DFs Consolidadas
A6: 5654834 | B6: LREN | C6: 20234T | D6: 45291 | E6: 45291 | F6: 1.01.02.01 | G6: Aplicações Financeiras Avaliadas a Valor Justo através do Resultado | H6: 571655 | I6: DFs Consolidadas
A7: 5654835 | B7: LREN | C7: 20234T | D7: 45291 | E7: 45291 | F7: 1.01.02.01.01 | G7: Títulos para Negociação | H7: 0 | I7: DFs Consolidadas
A8: 5654836 | B8: LREN | C8: 20234T | D8: 45291 | E8: 45291 | F8: 1.01.02.01.02 | G8: Títulos Designados a Valor Justo | H8: 571655 | I8: DFs Consolidadas
A9: 5654837 | B9: LREN | C9: 20234T | D9: 45291 | E9: 45291 | F9: 1.01.02.02 | G9: Aplicações Financeiras Avaliadas a Valor Justo através de Outros Resultados Abrangentes | H9: 0 | I9: DFs Consolidadas
A10: 5654838 | B10: LREN | C10: 20234T | D10: 45291 | E10: 45291 | F10: 1.01.02.03 | G10: Aplicações Financeiras Avaliadas ao Custo Amortizado | H10: 0 | I10: DFs Consolidadas
A11: 5654839 | B11: LREN | C11: 20234T | D11: 45291 | E11: 45291 | F11: 1.01.03 | G11: Contas a Receber | H11: 6639188 | I11: DFs Consolidadas
A12: 5654840 | B12: LREN | C12: 20234T | D12: 45291 | E12: 45291 | F12: 1.01.03.01 | G12: Clientes | H12: 6639188 | I12: DFs Consolidadas
A13: 5654841 | B13: LREN | C13: 20234T | D13: 45291 | E13: 45291 | F13: 1.01.03.02 | G13: Outras Contas a Receber | H13: 0 | I13: DFs Consolidadas
... A303: 5655131 | B303: LREN | C303: 20234T | D303: 44927 | E303: 45291 | F303: 7.08.05 | G303: Outros | H303: 0 | I303: DFs Consolidadas

Sheet 2025
A1: id | B1: empresa_tic | C1: ano_tri | D1: data_ini | E1: data_fim | F1: conta | G1: descricao | H1: valor | I1: tipo_balanco
A2: 6554474 | B2: LREN | C2: 20254T | D2: 46022 | E2: 46022 | F2: 1 | G2: Ativo Total | H2: 19626027 | I2: DFs Consolidadas
A3: 6554475 | B3: LREN | C3: 20254T | D3: 46022 | E3: 46022 | F3: 1.01 | G3: Ativo Circulante | H3: 11633757 | I3: DFs Consolidadas
A4: 6554476 | B4: LREN | C4: 20254T | D4: 46022 | E4: 46022 | F4: 1.01.01 | G4: Caixa e Equivalentes de Caixa | H4: 978066 | I4: DFs Consolidadas
A5: 6554477 | B5: LREN | C5: 20254T | D5: 46022 | E5: 46022 | F5: 1.01.02 | G5: Aplicações Financeiras | H5: 924745 | I5: DFs Consolidadas
A6: 6554478 | B6: LREN | C6: 20254T | D6: 46022 | E6: 46022 | F6: 1.01.02.01 | G6: Aplicações Financeiras Avaliadas a Valor Justo através do Resultado | H6: 924745 | I6: DFs Consolidadas
A7: 6554479 | B7: LREN | C7: 20254T | D7: 46022 | E7: 46022 | F7: 1.01.02.01.01 | G7: Títulos para Negociação | H7: 0 | I7: DFs Consolidadas
A8: 6554480 | B8: LREN | C8: 20254T | D8: 46022 | E8: 46022 | F8: 1.01.02.01.02 | G8: Títulos Designados a Valor Justo | H8: 924745 | I8: DFs Consolidadas
A9: 6554481 | B9: LREN | C9: 20254T | D9: 46022 | E9: 46022 | F9: 1.01.02.02 | G9: Aplicações Financeiras Avaliadas a Valor Justo através de Outros Resultados Abrangentes | H9: 0 | I9: DFs Consolidadas
A10: 6554482 | B10: LREN | C10: 20254T | D10: 46022 | E10: 46022 | F10: 1.01.02.03 | G10: Aplicações Financeiras Avaliadas ao Custo Amortizado | H10: 0 | I10: DFs Consolidadas
A11: 6554483 | B11: LREN | C11: 20254T | D11: 46022 | E11: 46022 | F11: 1.01.03 | G11: Contas a Receber | H11: 7175248 | I11: DFs Consolidadas
A12: 6554484 | B12: LREN | C12: 20254T | D12: 46022 | E12: 46022 | F12: 1.01.03.01 | G12: Clientes | H12: 7175248 | I12: DFs Consolidadas
A13: 6554485 | B13: LREN | C13: 20254T | D13: 46022 | E13: 46022 | F13: 1.01.03.02 | G13: Outras Contas a Receber | H13: 0 | I13: DFs Consolidadas
... A303: 6554775 | B303: LREN | C303: 20254T | D303: 45658 | E303: 46022 | F303: 7.08.05 | G303: Outros | H303: 0 | I303: DFs Consolidadas

Sheet 2024
A1: id | B1: empresa_tic | C1: ano_tri | D1: data_ini | E1: data_fim | F1: conta | G1: descricao | H1: valor | I1: tipo_balanco
A2: 6116364 | B2: LREN | C2: 20244T | D2: 45657 | E2: 45657 | F2: 1 | G2: Ativo Total | H2: 20364590 | I2: DFs Consolidadas
A3: 6116365 | B3: LREN | C3: 20244T | D3: 45657 | E3: 45657 | F3: 1.01 | G3: Ativo Circulante | H3: 12316659 | I3: DFs Consolidadas
A4: 6116366 | B4: LREN | C4: 20244T | D4: 45657 | E4: 45657 | F4: 1.01.01 | G4: Caixa e Equivalentes de Caixa | H4: 1926110 | I4: DFs Consolidadas
A5: 6116367 | B5: LREN | C5: 20244T | D5: 45657 | E5: 45657 | F5: 1.01.02 | G5: Aplicações Financeiras | H5: 845197 | I5: DFs Consolidadas
A6: 6116368 | B6: LREN | C6: 20244T | D6: 45657 | E6: 45657 | F6: 1.01.02.01 | G6: Aplicações Financeiras Avaliadas a Valor Justo através do Resultado | H6: 845197 | I6: DFs Consolidadas
A7: 6116369 | B7: LREN | C7: 20244T | D7: 45657 | E7: 45657 | F7: 1.01.02.01.01 | G7: Títulos para Negociação | H7: 0 | I7: DFs Consolidadas
A8: 6116370 | B8: LREN | C8: 20244T | D8: 45657 | E8: 45657 | F8: 1.01.02.01.02 | G8: Títulos Designados a Valor Justo | H8: 845197 | I8: DFs Consolidadas
A9: 6116371 | B9: LREN | C9: 20244T | D9: 45657 | E9: 45657 | F9: 1.01.02.02 | G9: Aplicações Financeiras Avaliadas a Valor Justo através de Outros Resultados Abrangentes | H9: 0 | I9: DFs Consolidadas
A10: 6116372 | B10: LREN | C10: 20244T | D10: 45657 | E10: 45657 | F10: 1.01.02.03 | G10: Aplicações Financeiras Avaliadas ao Custo Amortizado | H10: 0 | I10: DFs Consolidadas
A11: 6116373 | B11: LREN | C11: 20244T | D11: 45657 | E11: 45657 | F11: 1.01.03 | G11: Contas a Receber | H11: 6902933 | I11: DFs Consolidadas
A12: 6116374 | B12: LREN | C12: 20244T | D12: 45657 | E12: 45657 | F12: 1.01.03.01 | G12: Clientes | H12: 6902933 | I12: DFs Consolidadas
A13: 6116375 | B13: LREN | C13: 20244T | D13: 45657 | E13: 45657 | F13: 1.01.03.02 | G13: Outras Contas a Receber | H13: 0 | I13: DFs Consolidadas
... A188: 6116550 | B188: LREN | C188: 20244T | D188: 45292 | E188: 45657 | F188: 3.01.02 | G188: Receita líquida com produtos e serviços financeiros | H188: 1806510 | I188: DFs Consolidadas
A189: 6116551 | B189: LREN | C189: 20244T | D189: 45292 | E189: 45657 | F189: 3.02 | G189: Custo dos Bens e/ou Serviços Vendidos | H189: =ABS(H191) -> 55183 | I189: DFs Consolidadas
A190: 6116552 | B190: LREN | C190: 20244T | D190: 45292 | E190: 45657 | F190: 3.02.01 | G190: Custo das vendas com mercadorias | H190: -5639234 | I190: DFs Consolidadas
A191: 6116553 | B191: LREN | C191: 20244T | D191: 45292 | E191: 45657 | F191: 3.02.02 | G191: Custo dos produtos e serviços financeiros | H191: -55183 | I191: DFs Consolidadas
A192: 6116554 | B192: LREN | C192: 20244T | D192: 45292 | E192: 45657 | F192: 3.03 | G192: Resultado Bruto | H192: 8741949 | I192: DFs Consolidadas
A193: 6116555 | B193: LREN | C193: 20244T | D193: 45292 | E193: 45657 | F193: 3.04 | G193: Despesas/Receitas Operacionais | H193: -7482606 | I193: DFs Consolidadas
A194: 6116556 | B194: LREN | C194: 20244T | D194: 45292 | E194: 45657 | F194: 3.04.01 | G194: Despesas com Vendas | H194: -3881212 | I194: DFs Consolidadas
A195: 6116557 | B195: LREN | C195: 20244T | D195: 45292 | E195: 45657 | F195: 3.04.02 | G195: Despesas Gerais e Administrativas | H195: -1847770 | I195: DFs Consolidadas
A196: 6116558 | B196: LREN | C196: 20244T | D196: 45292 | E196: 45657 | F196: 3.04.03 | G196: Perdas pela Não Recuperabilidade de Ativos | H196: -957280 | I196: DFs Consolidadas
A197: 6116559 | B197: LREN | C197: 20244T | D197: 45292 | E197: 45657 | F197: 3.04.04 | G197: Outras Receitas Operacionais | H197: 210230 | I197: DFs Consolidadas
A198: 6116560 | B198: LREN | C198: 20244T | D198: 45292 | E198: 45657 | F198: 3.04.05 | G198: Outras Despesas Operacionais | H198: -1006574 | I198: DFs Consolidadas
A199: 6116561 | B199: LREN | C199: 20244T | D199: 45292 | E199: 45657 | F199: 3.04.06 | G199: Resultado de Equivalência Patrimonial | H199: 0 | I199: DFs Consolidadas
A200: 6116562 | B200: LREN | C200: 20244T | D200: 45292 | E200: 45657 | F200: 3.05 | G200: Resultado Antes do Resultado Financeiro e dos Tributos | H200: 1259343 | I200: DFs Consolidadas
A201: 6116563 | B201: LREN | C201: 20244T | D201: 45292 | E201: 45657 | F201: 3.06 | G201: Resultado Financeiro | H201: 61654 | I201: DFs Consolidadas
... A300: 6116662 | B300: LREN | C300: 20244T | D300: 45292 | E300: 45657 | F300: 7.08.05 | G300: Outros | H300: 0 | I300: DFs Consolidadas

Sheet Dados
A1: Indicadores | B1: 2025 | C1: 2024
A2: CCL (AC-PC) | B2: ='2025'!H3-'2025'!H71 -> 4767023
A3: LC (AC/PC) | B3: ='2025'!H3/'2025'!H71 -> 1.6942198 | C3: ='2024'!H3 / '2024'!H69 -> 1.6105351
A4: LS ((AC-EST-DA)/PC) | B4: =(('2025'!H3-'2025'!H14-'2025'!H20)/'2025'!H71) -> 1.4224898 | C4: =(('2024'!H3-'2024'!H14-'2024'!H18)/'2024'!H69) -> 1.358179
A5: LA ( Caixa e Equivalentes/PC) | B5: ='2025'!H4/'2025'!H71 -> 0.1424354 | C5: ='2024'!H4/'2024'!H69 -> 0.25185952
A6: LG ((AC + ARLG)/(PC+PNC)) | B6: =('2025'!H3+'2025'!H29)/('2025'!H71+'2025'!H123) -> 2.1403021 | C6: =('2024'!H3+'2024'!H27)/('2024'!H69+'2024'!H121) -> 2.1231606
A7: PME ((EST.INI +EST.FIN)/2)x360/CMV) | B7: =((('2024'!H14+'2025'!H14)/2)*360/ABS('2025'!H190)) -> 338.32455
A8: Giro de Estoque (CMV/EM) | B8: =ABS('2025'!H190)+'2025'!H14-'2024'!H14 -> 1955486 | C8: =ABS('2024'!H190)+'2024'!H14-'2023'!H14 -> 5794933
A9: PMRV((CRM/RV) x 360) | B9: =((('2024'!H12+'2025'!H12)/2)/'2025'!H188)*360 -> 160.08585 | C9: =((('2023'!H12+'2024'!H12)/2)/'2024'!H186)*360 -> 168.8501
A10: Compras | B10: =ABS('2025'!H190)+'2025'!H14-'2024'!H14 -> 1955486 | C10: =ABS('2024'!H190)+'2024'!H14-'2023'!H14 -> 5794933
A11: PMPF (((FornecedorInic + FornecedorFin)/2)/Compras)x360 | B11: =((('2024'!H75+'2025'!H75)/2)/(ABS('2025'!H190)+'2025'!H14-'2024'!H14))*360 -> 204.79296 | C11: =((('2023'!H75+'2024'!H75)/2)/(ABS('2024'!H190)+'2024'!H14-'2023'!H14))*360 -> 111.74734
A12: Ciclo Operacional | B12: =B7+B9 -> 498.4104 | C12: =C7+C9 -> 168.8501
A13: Cico Financeiro | B13: =B7+B9-B11 -> 293.61745 | C13: =C7+C9-C11 -> 57.102754
A14: Ciclo Econômico | B14: =B7 -> 338.32455 | C14: =C7 -> 0
A15: Ativo Circulante Financeiro - ACF | B15: ='2025'!H4+'2025'!H5 -> 1902811 | C15: ='2024'!H4+'2024'!H5 -> 2771307
A16: Ativo Circulante Operacional - ACO | B16: ='2025'!H11+'2025'!H14+'2025'!H16+'2025'!H19 -> 9756562 | C16: ='2024'!H11+'2024'!H14+'2024'!H16+'2024'!H19 -> 9545352
A17: Ativo circulante | B17: =B15+B16 -> 11659373 | C17: =C15+C16 -> 12316659
A18: Passivo Circulante Financeiro - PCF | B18: ='2025'!H81+'2025'!H86+'2025'!H98+'2025'!H103+'2025'!H104 -> 890572 | C18: ='2024'!H81+'2024'!H86+'2024'!H98+'2024'!H103+'2024'!H104 -> 3947948
A19: Passivo Circulante Operacional - PCO | B19: =B20-B18 -> 5976162 | C19: ='2024'!H70+'2024'!H75+'2024'!H84+'2024'!H85+'2024'!H102+'2024'!H106+'2024'!H107 -> 3699609
A20: Passivo Circulante | B20: ='2025'!H71 -> 6866734 | C20: =C18+C19 -> 7647557
A21: Saldo em Tesouraria - ST (ACF-PCF) | B21: =B15-B18 -> 1012239 | C21: =C15-C18 -> -1176641
B22: 2025 | C22: 2024
A23: Necessidade de Capital de Giro - NCG (ACO-PCO) | B23: =B16-B19 -> 3780400 | C23: =C16-C19 -> 5845743
A24: Capital de Giro Líquido - CGL (AC-PC) | B24: =B17-B20 -> 4792639 | C24: =C17-C20 -> 4669102
A25: Relações de Capitais (Passivo/PL) | B25: ='2025'!H70/'2025'!H162 -> 1.8769606 | C25: ='2024'!H68/'2024'!H160 -> 1.8903446
A26: Endividamento Geral (Passivo/(Passivo+PL) | B26: ='2025'!H70/('2025'!H70+'2025'!H162) -> 0.65241095 | C26: ='2024'!H68/('2024'!H68+'2024'!H160) -> 0.6540205
A27: Solvência Geral (Ativo/Passivo) | B27: ='2025'!H2/'2025'!H70 -> 1 | C27: ='2024'!H2/'2024'!H68 -> 1
A28: Composição do Endividamento (PC/Passivo) | B28: =B20/'2025'!H70 -> 0.34987896 | C28: =C20/'2024'!H68 -> 0.37553209
A29: Imobilização do PL (Ativos Fixos/PL) | B29: =('2025'!H60+'2025'!H64)/'2025'!H162 -> 0.63280109 | C29: =('2024'!H58+'2024'!H62)/'2024'!H160 -> 0.62809299
A31: Número de ações da empresa | B31: 1006845
A32: Preço da ação | B32: 13.55
A33: VPA (PL/n de ações) | B33: ='2025'!H162/Dados!B31 -> 10.385194
A34: PVP (Preço da ação/VPA) 13/05/2026 | B34: =13.55/Dados!B33 -> 1.3047421
A35: LPA (Lucro líquido/ n de ações) | B35: ='2025'!H214/Dados!B31 -> 1.4476568
A36: P/L (Preço da ação/LPA) | B36: =13.55/B35 -> 9.3599533
A37: DPA (Valor dos dividendos anuais)

Sheet Indicadores
A1: Indicadores de Liquidez | B1: Sigla | C1: Fórmulas | E1: 2025 | F1: 2024
A2: Capital Circulante Líquido | B2: CCL | C2: AC - PC | E2: ='2025'!H3-'2025'!H71 -> 4767023 | F2: ='2024'!H3 - '2024'!H69 -> 4669102
A3: Índice de Liquides Corrente | B3: LC | C3: AC/PC | E3: ='2025'!H3/'2025'!H71 -> 1.6942198 | F3: ='2024'!H3 / '2024'!H69 -> 1.6105351
A4: Índice de Liquides Seca | B4: LS | C4: (AC - EST - DA) /PC | E4: =(('2025'!H3-'2025'!H14-'2025'!H20)/'2025'!H71) -> 1.4224898 | F4: =(('2024'!H3-'2024'!H14-'2024'!H18)/'2024'!H69) -> 1.358179
A5: Índice de Liquides Absoluta | B5: LA | C5: DISPONIVEL /PC | E5: ='2025'!H4/'2025'!H71 -> 0.1424354 | F5: ='2024'!H4/'2024'!H69 -> 0.25185952
A6: Índice de Liquides Geral | B6: LG | C6: AC + ARLP / PC +PNC | E6: =('2025'!H3+'2025'!H29)/('2025'!H71+'2025'!H123) -> 2.1403021 | F6: =('2024'!H3+'2024'!H27)/('2024'!H69+'2024'!H121) -> 2.1231606
A8: Indicadores de Atividade | B8: Sigla | C8: Fórmulas | E8: 2025 | F8: 2024
A9: Prazo Médio de Estocagem | B9: PME | C9: (ESTOQUE MÉDIO/CMV)*360 | E9: =((('2024'!H14+'2025'!H14)/2)*360/ABS('2025'!H190)) -> 338.32455 | F9: =((('2023'!H14+'2024'!H14)/2)/ABS('2024'!H190))*360 -> 118.23256
A10: Giro do Estoque | B10: GE | C10: 360/PME | E10: =360/E9 -> 1.064067 | F10: =360/F9 -> 3.0448466
A11: Prazo Médio de Recebimento de Vendas | B11: PMRV | C11: (CLIENTES MÉDIO /RECEITA)*360 | E11: =((('2024'!H12+'2025'!H12)/2)/'2025'!H188)*360 -> 160.08585 | F11: =((('2023'!H12+'2024'!H12)/2)/'2024'!H186)*360 -> 168.8501
A12: Prazo Médio de Pagamento de Fornecedores | B12: PMPF | C12: (FORNECEDORES MÉDIO/COMPRAS)*360 | E12: =ABS('2025'!H190)+'2025'!H14-'2024'!H14 -> 1955486 | F12: =ABS('2024'!H190)+'2024'!H14-'2023'!H14 -> 5794933
A13: Ciclo Operacional | B13: CO | C13: PME+PMRV | E13: =((('2024'!H75+'2025'!H75)/2)/(ABS('2025'!H190)+'2025'!H14-'2024'!H14))*360 -> 204.79296 | F13: =((('2023'!H75+'2024'!H75)/2)/(ABS('2024'!H190)+'2024'!H14-'2023'!H14))*360 -> 111.74734
A14: Ciclo Financeiro | B14: CF | C14: CO-PMPF | E14: =E9+E11 -> 498.4104 | F14: =F9+F11 -> 287.08265
A15: Ciclo Econômico | B15: CE | C15: PME | E15: =E9 -> 338.32455 | F15: =F9 -> 118.23256
A17: Indicadores de Capital de Giro | B17: Sigla | C17: Fórmulas | E17: 2025 | F17: 2024
A18: Capital de Giro Líquido | B18: CDG | C18: CDG = AC - PC | E18: ='2025'!H3-'2025'!H71 -> 4767023 | F18: ='2024'!H3-'2024'!H69 -> 4669102
A19: Saldo em Tesouraria | B19: ST | C19: ST = ACF - PCF | E19: =('2025'!H4+'2025'!H5)-'2025'!H75 -> 1485291 | F19: =('2024'!H4+'2024'!H5)-'2024'!H73 -> 2397187
A20: Necessidade de Capital de Giro | B20: NCG | C20: NCG = ACO - PCO | E20: =('2025'!H20+'2025'!H14)-'2025'!H75 -> 1448378 | F20: =('2024'!H18+'2024'!H14)-'2024'!H73 -> 1555788
A22: Indicadores de Estrutura de Capital | B22: Sigla | C22: Fórmulas | E22: 2025 | F22: 2024
A23: Relação de Capital Próprio e de Terceiros | B23: RCPT | C23: PASSIVO/PL | E23: ='2025'!H126/'2025'!H123 -> 0.15579076 | F23: ='2024'!H124/'2024'!H121 -> 0.0070676031
A24: Endividamento Geral | B24: EG | C24: PASSIVO/PASSIVO+PL | E24: ='2025'!H126/'2025'!H194 -> 0.036731402 | F24: ='2024'!H124/'2024'!H192 -> 0.0015717319
A25: Solvência Geral | B25: SG | C25: ATIVO TOTAL/PASSIVO | E25: ='2025'!H194/'2025'!H126 -> 27.224662 | F25: ='2024'!H192/'2024'!H124 -> 636.24083
A26: Composição do Endividamento | B26: CE | C26: PC/PASSIVO | E26: ='2025'!H71/'2025'!H126 -> 19.138695 | F26: ='2024'!H69/'2024'!H124 -> 556.59076
A27: Imobilização do Patrimônio Líquido | B27: IPL | C27: ATIVOS FIXOS(3is)/PL | E27: ='2025'!H60/'2025'!H126 -> 13.951927 | F27: ='2024'!H60/'2024'!H124 -> 163.94054
A28: Passivo Oneroso | B28: PO | C28: PASSIVOS QUE GERAM DESPESAS FINANCEIRAS | E28: ='2025'!H123 -> 2303012 | F28: ='2024'!H121 -> 1944082
A29: Dívida Líquida | B29: DL | C29: PO - (DISPONÍVEL + AP. FINANCEIRA) | E29: ='2025'!H123-('2025'!H4+'2025'!H5) -> 400201 | F29: ='2024'!H121-('2024'!H4+'2024'!H5) -> -827225
A30: Investimento | B30: INV | C30: PO + PL | E30: ='2025'!H123+'2025'!H128 -> 2303012 | F30: ='2024'!H121+'2024'!H126 -> 1944082
A31: Capital Oneroso | B31: CO | C31: DÍVIDA LÍQUIDA + PL | E31: =E29+'2025'!H126 -> 758989 | F31: =F29+'2024'!H124 -> -813485
A32: Relação dívida Líquida - PL | B32: na | C32: DL/PL | E32: =E29/'2025'!H126 -> 1.1154247 | F32: =F29/'2024'!H124 -> -60.205604
A33: Relação divida líquida e CO | B33: na | C33: DÍVIDA LÍQUIDA /dívida líquida + PL | E33: =E29/E31 -> 0.52728169 | F33: =F29/F31 -> 1.0168903
A35: Indicadores de Custo do Capital | B35: Sigla | C35: Fórmulas | E35: 2025 | F35: 2024
A36: Percentual da Dívida no Investimento | B36: Wi | C36: PO/Investimento
A37: Percentual da Equity no Investimento | B37: We | C37: PL/Investimento
A38: Despesa Financeira Líquida | B38: DFL | C38: DF - BENEFÍCIO TRIBUTÁRIO
A39: Benefício Tributário da Dívida | B39: BT | C39: DESPESA FINANCEIRA X ALÍQUOTA IR/CSLL
A40: Aliquota Efetiva IR/CSLL | B40: % IR | C40: PROVISÃO IR/CSLL / LAIR
A41: Custo da Dívida | B41: Ki | C41: Despesa financeira / PO
A42: Custo Médio Ponderado de Capital | B42: CMPC | C42: Wi x Ki + We x Ke | E42: 0.2049
A44: Indicadores de Lucratividade e Rentabilidade | B44: Sigla | C44: Fórmulas | E44: 2025 | F44: 2024
A45: Margem Bruta | B45: MB | C45: LUCRO BRUTO/RECEITA LÍQUIDA | E45: ='2025'!H194/DRE!B2 -> 0.61706982 | F45: ='2024'!H192/DRE!C2 -> 0.60555052
...

Sheet DRE
A1: DRE Gerencial | B1: 2025 | C1: 2024
A2: Receita Líquida | B2: ='2025'!H188 -> 15829460 | C2: ='2024'!H186 -> 14436366
A3: Lucro Bruto | B3: ='2025'!H164 -> -334173 | C3: ='2024'!H162 -> 12054
A4: EBIT | B4: ='2025'!H172 -> 1148816 | C4: ='2024'!H170 -> 1078994
A5: EBITDA | B5: =B4+'2025'!H225 -> 2439774 | C5: =C4+'2024'!H223 -> 2323248
A6: NOPAT | B6: =B4-ABS('2025'!H178) -> 1148816 | C6: =C4-ABS('2024'!H176) -> 1078994
